WARNING:torch.distributed.run:
*****************************************
Setting OMP_NUM_THREADS environment variable for each process to be 1 in default, to avoid your system being overloaded, please further tune the variable for optimal performance in your application as needed. 
*****************************************
[2024-12-24 10:53:09,171] [INFO] [real_accelerator.py:158:get_accelerator] Setting ds_accelerator to cuda (auto detect)
[2024-12-24 10:53:09,171] [INFO] [real_accelerator.py:158:get_accelerator] Setting ds_accelerator to cuda (auto detect)
[2024-12-24 10:53:09,173] [INFO] [real_accelerator.py:158:get_accelerator] Setting ds_accelerator to cuda (auto detect)
[2024-12-24 10:53:09,174] [INFO] [real_accelerator.py:158:get_accelerator] Setting ds_accelerator to cuda (auto detect)
[2024-12-24 10:53:09,180] [INFO] [real_accelerator.py:158:get_accelerator] Setting ds_accelerator to cuda (auto detect)
[2024-12-24 10:53:09,181] [INFO] [real_accelerator.py:158:get_accelerator] Setting ds_accelerator to cuda (auto detect)
[2024-12-24 10:53:09,190] [INFO] [real_accelerator.py:158:get_accelerator] Setting ds_accelerator to cuda (auto detect)
[2024-12-24 10:53:09,191] [INFO] [real_accelerator.py:158:get_accelerator] Setting ds_accelerator to cuda (auto detect)
Traceback (most recent call last):
  File "/home/wangxinrong/workspace/reft/divination/mwp_ReFT/train_sft_model.py", line 30, in <module>
    import wandb
ModuleNotFoundError: No module named 'wandb'
Traceback (most recent call last):
  File "/home/wangxinrong/workspace/reft/divination/mwp_ReFT/train_sft_model.py", line 30, in <module>
    import wandb
ModuleNotFoundError: No module named 'wandb'
Traceback (most recent call last):
  File "/home/wangxinrong/workspace/reft/divination/mwp_ReFT/train_sft_model.py", line 30, in <module>
    import wandb
ModuleNotFoundError: No module named 'wandb'
Traceback (most recent call last):
  File "/home/wangxinrong/workspace/reft/divination/mwp_ReFT/train_sft_model.py", line 30, in <module>
    import wandb
ModuleNotFoundError: No module named 'wandb'
Traceback (most recent call last):
  File "/home/wangxinrong/workspace/reft/divination/mwp_ReFT/train_sft_model.py", line 30, in <module>
    import wandb
ModuleNotFoundError: No module named 'wandb'
Traceback (most recent call last):
  File "/home/wangxinrong/workspace/reft/divination/mwp_ReFT/train_sft_model.py", line 30, in <module>
    import wandb
ModuleNotFoundError: No module named 'wandb'
Traceback (most recent call last):
  File "/home/wangxinrong/workspace/reft/divination/mwp_ReFT/train_sft_model.py", line 30, in <module>
    import wandb
ModuleNotFoundError: No module named 'wandb'
Traceback (most recent call last):
  File "/home/wangxinrong/workspace/reft/divination/mwp_ReFT/train_sft_model.py", line 30, in <module>
    import wandb
ModuleNotFoundError: No module named 'wandb'
ERROR:torch.distributed.elastic.multiprocessing.api:failed (exitcode: 1) local_rank: 0 (pid: 2434442) of binary: /home/wangxinrong/miniconda3/envs/cuda-11.7/bin/python
Traceback (most recent call last):
  File "/home/wangxinrong/miniconda3/envs/cuda-11.7/bin/accelerate", line 8, in <module>
    sys.exit(main())
  File "/home/wangxinrong/miniconda3/envs/cuda-11.7/lib/python3.10/site-packages/accelerate/commands/accelerate_cli.py", line 47, in main
    args.func(args)
  File "/home/wangxinrong/miniconda3/envs/cuda-11.7/lib/python3.10/site-packages/accelerate/commands/launch.py", line 971, in launch_command
    deepspeed_launcher(args)
  File "/home/wangxinrong/miniconda3/envs/cuda-11.7/lib/python3.10/site-packages/accelerate/commands/launch.py", line 687, in deepspeed_launcher
    distrib_run.run(args)
  File "/home/wangxinrong/miniconda3/envs/cuda-11.7/lib/python3.10/site-packages/torch/distributed/run.py", line 785, in run
    elastic_launch(
  File "/home/wangxinrong/miniconda3/envs/cuda-11.7/lib/python3.10/site-packages/torch/distributed/launcher/api.py", line 134, in __call__
    return launch_agent(self._config, self._entrypoint, list(args))
  File "/home/wangxinrong/miniconda3/envs/cuda-11.7/lib/python3.10/site-packages/torch/distributed/launcher/api.py", line 250, in launch_agent
    raise ChildFailedError(
torch.distributed.elastic.multiprocessing.errors.ChildFailedError: 
============================================================
train_sft_model.py FAILED
------------------------------------------------------------
Failures:
[1]:
  time      : 2024-12-24_10:53:16
  host      : HS-DSS8440-009
  rank      : 1 (local_rank: 1)
  exitcode  : 1 (pid: 2434443)
  error_file: <N/A>
  traceback : To enable traceback see: https://pytorch.org/docs/stable/elastic/errors.html
[2]:
  time      : 2024-12-24_10:53:16
  host      : HS-DSS8440-009
  rank      : 2 (local_rank: 2)
  exitcode  : 1 (pid: 2434444)
  error_file: <N/A>
  traceback : To enable traceback see: https://pytorch.org/docs/stable/elastic/errors.html
[3]:
  time      : 2024-12-24_10:53:16
  host      : HS-DSS8440-009
  rank      : 3 (local_rank: 3)
  exitcode  : 1 (pid: 2434445)
  error_file: <N/A>
  traceback : To enable traceback see: https://pytorch.org/docs/stable/elastic/errors.html
[4]:
  time      : 2024-12-24_10:53:16
  host      : HS-DSS8440-009
  rank      : 4 (local_rank: 4)
  exitcode  : 1 (pid: 2434446)
  error_file: <N/A>
  traceback : To enable traceback see: https://pytorch.org/docs/stable/elastic/errors.html
[5]:
  time      : 2024-12-24_10:53:16
  host      : HS-DSS8440-009
  rank      : 5 (local_rank: 5)
  exitcode  : 1 (pid: 2434447)
  error_file: <N/A>
  traceback : To enable traceback see: https://pytorch.org/docs/stable/elastic/errors.html
[6]:
  time      : 2024-12-24_10:53:16
  host      : HS-DSS8440-009
  rank      : 6 (local_rank: 6)
  exitcode  : 1 (pid: 2434448)
  error_file: <N/A>
  traceback : To enable traceback see: https://pytorch.org/docs/stable/elastic/errors.html
[7]:
  time      : 2024-12-24_10:53:16
  host      : HS-DSS8440-009
  rank      : 7 (local_rank: 7)
  exitcode  : 1 (pid: 2434449)
  error_file: <N/A>
  traceback : To enable traceback see: https://pytorch.org/docs/stable/elastic/errors.html
------------------------------------------------------------
Root Cause (first observed failure):
[0]:
  time      : 2024-12-24_10:53:16
  host      : HS-DSS8440-009
  rank      : 0 (local_rank: 0)
  exitcode  : 1 (pid: 2434442)
  error_file: <N/A>
  traceback : To enable traceback see: https://pytorch.org/docs/stable/elastic/errors.html
============================================================
